Workbook

Sheet Задача1
A1: Вершков Максим, вариант 1
A2: Всего предприятий | D2: 100
A3: Отбираем 10% | D3: =D2*10% -> 10
A5: строка | B5: 1 | C5: 2 | D5: 3 | E5: 4 | F5: 5 | G5: 6 | H5: 7
A6: 1 | B6: 1967 | C6: 1741 | D6: 7932 | E6: 6959 | F6: 5567 | G6: 8128 | H6: 1144
A7: 2 | B7: 9732 | C7: 1451 | D7: 659 | E7: 3345 | F7: 1113 | G7: 397 | H7: 9511
A8: 3 | B8: 1416 | C8: 6736 | D8: 7193 | E8: 1262 | F8: 6458 | G8: 3263 | H8: 2428
A9: 4 | B9: 9122 | C9: 5626 | D9: 1883 | E9: 7792 | F9: 8479 | G9: 805 | H9: 6618
A10: 5 | B10: 7067 | C10: 2690 | D10: 717 | E10: 4699 | F10: 5807 | G10: 3323 | H10: 4174
A11: 6 | B11: 5372 | C11: 3740 | D11: 6882 | E11: 5587 | F11: 1360 | G11: 962 | H11: 3305
A12: 7 | B12: 4968 | C12: 2156 | D12: 2585 | E12: 4012 | F12: 8800 | G12: 8330 | H12: 5875
A13: 8 | B13: 4157 | C13: 5100 | D13: 1585 | E13: 2383 | F13: 5100 | G13: 2912 | H13: 3635
A14: 9 | B14: 6409 | C14: 1323 | D14: 6914 | E14: 4813 | F14: 6391 | G14: 7252 | H14: 9593
A15: 10 | B15: 3019 | C15: 3672 | D15: 7946 | E15: 6518 | F15: 6988 | G15: 1628 | H15: 9393
A17: Старт (строка, случайно от 1 до 7) | E17: 3
A18: Читаю строку слева направо, беру первые две цифры числа (00 = 100)
A20: Число | B20: Первые 2 цифры | C20: Повтор? | D20: Номер
A21: =B8 -> 1416 | B21: =IF(INT(A21/100)=0,100,INT(A21/100)) -> 14 | C21: =IF(COUNTIF(B$20:B20,B21)>0,"да","нет") -> нет | D21: =IF(C21="нет",B21,"") -> 14
A22: =C8 -> 6736 | B22: =IF(INT(A22/100)=0,100,INT(A22/100)) -> 67 | C22: =IF(COUNTIF(B$20:B21,B22)>0,"да","нет") -> нет | D22: =IF(C22="нет",B22,"") -> 67
A23: =D8 -> 7193 | B23: =IF(INT(A23/100)=0,100,INT(A23/100)) -> 71 | C23: =IF(COUNTIF(B$20:B22,B23)>0,"да","нет") -> нет | D23: =IF(C23="нет",B23,"") -> 71
A24: =E8 -> 1262 | B24: =IF(INT(A24/100)=0,100,INT(A24/100)) -> 12 | C24: =IF(COUNTIF(B$20:B23,B24)>0,"да","нет") -> нет | D24: =IF(C24="нет",B24,"") -> 12
A25: =F8 -> 6458 | B25: =IF(INT(A25/100)=0,100,INT(A25/100)) -> 64 | C25: =IF(COUNTIF(B$20:B24,B25)>0,"да","нет") -> нет | D25: =IF(C25="нет",B25,"") -> 64
A26: =G8 -> 3263 | B26: =IF(INT(A26/100)=0,100,INT(A26/100)) -> 32 | C26: =IF(COUNTIF(B$20:B25,B26)>0,"да","нет") -> нет | D26: =IF(C26="нет",B26,"") -> 32
A27: =H8 -> 2428 | B27: =IF(INT(A27/100)=0,100,INT(A27/100)) -> 24 | C27: =IF(COUNTIF(B$20:B26,B27)>0,"да","нет") -> нет | D27: =IF(C27="нет",B27,"") -> 24
A28: =B9 -> 9122 | B28: =IF(INT(A28/100)=0,100,INT(A28/100)) -> 91 | C28: =IF(COUNTIF(B$20:B27,B28)>0,"да","нет") -> нет | D28: =IF(C28="нет",B28,"") -> 91
A29: =C9 -> 5626 | B29: =IF(INT(A29/100)=0,100,INT(A29/100)) -> 56 | C29: =IF(COUNTIF(B$20:B28,B29)>0,"да","нет") -> нет | D29: =IF(C29="нет",B29,"") -> 56
A30: =D9 -> 1883 | B30: =IF(INT(A30/100)=0,100,INT(A30/100)) -> 18 | C30: =IF(COUNTIF(B$20:B29,B30)>0,"да","нет") -> нет | D30: =IF(C30="нет",B30,"") -> 18
A32: Выборка по возрастанию:
B33: =SMALL($D$21:$D$30,1) -> 12 | C33: =SMALL($D$21:$D$30,2) -> 14 | D33: =SMALL($D$21:$D$30,3) -> 18 | E33: =SMALL($D$21:$D$30,4) -> 24 | F33: =SMALL($D$21:$D$30,5) -> 32 | G33: =SMALL($D$21:$D$30,6) -> 56 | H33: =SMALL($D$21:$D$30,7) -> 64 | I33: =SMALL($D$21:$D$30,8) -> 67 | J33: =SMALL($D$21:$D$30,9) -> 71 | K33: =SMALL($D$21:$D$30,10) -> 91

Sheet Задача2
A1: Фамилия на В - колонка 2 табл. 1 приложения 1
A2: Из 10 предприятий задачи 1 случайно без повторения выбираем 3
A4: Количество сочетаний | D4: =COMBIN(10,3) -> 120
A6: № | B6: =Задача1!B33 -> 12 | C6: =Задача1!C33 -> 14 | D6: =Задача1!D33 -> 18 | E6: =Задача1!E33 -> 24 | F6: =Задача1!F33 -> 32 | G6: =Задача1!G33 -> 56 | H6: =Задача1!H33 -> 64 | I6: =Задача1!I33 -> 67 | ... K6: =Задача1!K33 -> 91 | L6: Σx
A7: x | L7: =SUM(B7:K7) -> 0
A8: (x - значения колонки 2 из приложения 1)
A10: x̄ген = Σx / 10 | D10: =L7/10 -> 0
A12: Выбор трех: дальше по той же таблице (4 строка, 4 число), первая цифра = порядковый номер (0 -> 10)
A13: Число | B13: Первая цифра | C13: Порядк. № | D13: № предпр. | E13: x
A14: =Задача1!E9 -> 7792 | B14: =INT(A14/1000) -> 7 | C14: =IF(B14=0,10,B14) -> 7 | D14: =INDEX($B$6:$K$6,C14) -> 64 | E14: =INDEX($B$7:$K$7,C14) -> 0
A15: =Задача1!F9 -> 8479 | B15: =INT(A15/1000) -> 8 | C15: =IF(B15=0,10,B15) -> 8 | D15: =INDEX($B$6:$K$6,C15) -> 67 | E15: =INDEX($B$7:$K$7,C15) -> 0
A16: =Задача1!G9 -> 805 | B16: =INT(A16/1000) -> 0 | C16: =IF(B16=0,10,B16) -> 10 | D16: =INDEX($B$6:$K$6,C16) -> 91 | E16: =INDEX($B$7:$K$7,C16) -> 0
A18: x̄выб = | D18: =SUM(E14:E16)/3 -> 0
A19: отклонение x̄выб - x̄ген | D19: =D18-D10 -> 0
A21: Несмещенность (перебор всех 120 выборок на листе Выборки)
A22: среднее всех выборочных средних | D22: =AVERAGE(Выборки!F2:F121) -> 0
A23: x̄ген | D23: =D10 -> 0
A24: =IF(COUNT(B7:K7)<10,"впиши значения x из приложения 1",IF(ABS(D22-D23)<0.000001,"Совпадает, значит выборочная средняя несмещенная","Не совпадает")) -> впиши значения x из приложения 1

Sheet Выборки
A1: № | B1: Предприятия | C1: x1 | D1: x2 | E1: x3 | F1: Средняя | H1: min | I1: =MIN(F2:F121) -> 0
A2: 1 | B2: =INDEX(Задача2!$B$6:$K$6,1)&"-"&INDEX(Задача2!$B$6:$K$6,2)&"-"&INDEX(Задача2!$B$6:$K$6,3) -> 12-14-18 | C2: =INDEX(Задача2!$B$7:$K$7,1) -> 0 | D2: =INDEX(Задача2!$B$7:$K$7,2) -> 0 | E2: =INDEX(Задача2!$B$7:$K$7,3) -> 0 | F2: =(C2+D2+E2)/3 -> 0 | H2: max | I2: =MAX(F2:F121) -> 0
A3: 2 | B3: =INDEX(Задача2!$B$6:$K$6,1)&"-"&INDEX(Задача2!$B$6:$K$6,2)&"-"&INDEX(Задача2!$B$6:$K$6,4) -> 12-14-24 | C3: =INDEX(Задача2!$B$7:$K$7,1) -> 0 | D3: =INDEX(Задача2!$B$7:$K$7,2) -> 0 | E3: =INDEX(Задача2!$B$7:$K$7,4) -> 0 | F3: =(C3+D3+E3)/3 -> 0
A4: 3 | B4: =INDEX(Задача2!$B$6:$K$6,1)&"-"&INDEX(Задача2!$B$6:$K$6,2)&"-"&INDEX(Задача2!$B$6:$K$6,5) -> 12-14-32 | C4: =INDEX(Задача2!$B$7:$K$7,1) -> 0 | D4: =INDEX(Задача2!$B$7:$K$7,2) -> 0 | E4: =INDEX(Задача2!$B$7:$K$7,5) -> 0 | F4: =(C4+D4+E4)/3 -> 0
A5: 4 | B5: =INDEX(Задача2!$B$6:$K$6,1)&"-"&INDEX(Задача2!$B$6:$K$6,2)&"-"&INDEX(Задача2!$B$6:$K$6,6) -> 12-14-56 | C5: =INDEX(Задача2!$B$7:$K$7,1) -> 0 | D5: =INDEX(Задача2!$B$7:$K$7,2) -> 0 | E5: =INDEX(Задача2!$B$7:$K$7,6) -> 0 | F5: =(C5+D5+E5)/3 -> 0
A6: 5 | B6: =INDEX(Задача2!$B$6:$K$6,1)&"-"&INDEX(Задача2!$B$6:$K$6,2)&"-"&INDEX(Задача2!$B$6:$K$6,7) -> 12-14-64 | C6: =INDEX(Задача2!$B$7:$K$7,1) -> 0 | D6: =INDEX(Задача2!$B$7:$K$7,2) -> 0 | E6: =INDEX(Задача2!$B$7:$K$7,7) -> 0 | F6: =(C6+D6+E6)/3 -> 0
A7: 6 | B7: =INDEX(Задача2!$B$6:$K$6,1)&"-"&INDEX(Задача2!$B$6:$K$6,2)&"-"&INDEX(Задача2!$B$6:$K$6,8) -> 12-14-67 | C7: =INDEX(Задача2!$B$7:$K$7,1) -> 0 | D7: =INDEX(Задача2!$B$7:$K$7,2) -> 0 | E7: =INDEX(Задача2!$B$7:$K$7,8) -> 0 | F7: =(C7+D7+E7)/3 -> 0
A8: 7 | B8: =INDEX(Задача2!$B$6:$K$6,1)&"-"&INDEX(Задача2!$B$6:$K$6,2)&"-"&INDEX(Задача2!$B$6:$K$6,9) -> 12-14-71 | C8: =INDEX(Задача2!$B$7:$K$7,1) -> 0 | D8: =INDEX(Задача2!$B$7:$K$7,2) -> 0 | E8: =INDEX(Задача2!$B$7:$K$7,9) -> 0 | F8: =(C8+D8+E8)/3 -> 0
A9: 8 | B9: =INDEX(Задача2!$B$6:$K$6,1)&"-"&INDEX(Задача2!$B$6:$K$6,2)&"-"&INDEX(Задача2!$B$6:$K$6,10) -> 12-14-91 | C9: =INDEX(Задача2!$B$7:$K$7,1) -> 0 | D9: =INDEX(Задача2!$B$7:$K$7,2) -> 0 | E9: =INDEX(Задача2!$B$7:$K$7,10) -> 0 | F9: =(C9+D9+E9)/3 -> 0
A10: 9 | B10: =INDEX(Задача2!$B$6:$K$6,1)&"-"&INDEX(Задача2!$B$6:$K$6,3)&"-"&INDEX(Задача2!$B$6:$K$6,4) -> 12-18-24 | C10: =INDEX(Задача2!$B$7:$K$7,1) -> 0 | D10: =INDEX(Задача2!$B$7:$K$7,3) -> 0 | E10: =INDEX(Задача2!$B$7:$K$7,4) -> 0 | F10: =(C10+D10+E10)/3 -> 0
A11: 10 | B11: =INDEX(Задача2!$B$6:$K$6,1)&"-"&INDEX(Задача2!$B$6:$K$6,3)&"-"&INDEX(Задача2!$B$6:$K$6,5) -> 12-18-32 | C11: =INDEX(Задача2!$B$7:$K$7,1) -> 0 | D11: =INDEX(Задача2!$B$7:$K$7,3) -> 0 | E11: =INDEX(Задача2!$B$7:$K$7,5) -> 0 | F11: =(C11+D11+E11)/3 -> 0
A12: 11 | B12: =INDEX(Задача2!$B$6:$K$6,1)&"-"&INDEX(Задача2!$B$6:$K$6,3)&"-"&INDEX(Задача2!$B$6:$K$6,6) -> 12-18-56 | C12: =INDEX(Задача2!$B$7:$K$7,1) -> 0 | D12: =INDEX(Задача2!$B$7:$K$7,3) -> 0 | E12: =INDEX(Задача2!$B$7:$K$7,6) -> 0 | F12: =(C12+D12+E12)/3 -> 0
A13: 12 | B13: =INDEX(Задача2!$B$6:$K$6,1)&"-"&INDEX(Задача2!$B$6:$K$6,3)&"-"&INDEX(Задача2!$B$6:$K$6,7) -> 12-18-64 | C13: =INDEX(Задача2!$B$7:$K$7,1) -> 0 | D13: =INDEX(Задача2!$B$7:$K$7,3) -> 0 | E13: =INDEX(Задача2!$B$7:$K$7,7) -> 0 | F13: =(C13+D13+E13)/3 -> 0
A14: 13 | B14: =INDEX(Задача2!$B$6:$K$6,1)&"-"&INDEX(Задача2!$B$6:$K$6,3)&"-"&INDEX(Задача2!$B$6:$K$6,8) -> 12-18-67 | C14: =INDEX(Задача2!$B$7:$K$7,1) -> 0 | D14: =INDEX(Задача2!$B$7:$K$7,3) -> 0 | E14: =INDEX(Задача2!$B$7:$K$7,8) -> 0 | F14: =(C14+D14+E14)/3 -> 0
A15: 14 | B15: =INDEX(Задача2!$B$6:$K$6,1)&"-"&INDEX(Задача2!$B$6:$K$6,3)&"-"&INDEX(Задача2!$B$6:$K$6,9) -> 12-18-71 | C15: =INDEX(Задача2!$B$7:$K$7,1) -> 0 | D15: =INDEX(Задача2!$B$7:$K$7,3) -> 0 | E15: =INDEX(Задача2!$B$7:$K$7,9) -> 0 | F15: =(C15+D15+E15)/3 -> 0
A16: 15 | B16: =INDEX(Задача2!$B$6:$K$6,1)&"-"&INDEX(Задача2!$B$6:$K$6,3)&"-"&INDEX(Задача2!$B$6:$K$6,10) -> 12-18-91 | C16: =INDEX(Задача2!$B$7:$K$7,1) -> 0 | D16: =INDEX(Задача2!$B$7:$K$7,3) -> 0 | E16: =INDEX(Задача2!$B$7:$K$7,10) -> 0 | F16: =(C16+D16+E16)/3 -> 0
A17: 16 | B17: =INDEX(Задача2!$B$6:$K$6,1)&"-"&INDEX(Задача2!$B$6:$K$6,4)&"-"&INDEX(Задача2!$B$6:$K$6,5) -> 12-24-32 | C17: =INDEX(Задача2!$B$7:$K$7,1) -> 0 | D17: =INDEX(Задача2!$B$7:$K$7,4) -> 0 | E17: =INDEX(Задача2!$B$7:$K$7,5) -> 0 | F17: =(C17+D17+E17)/3 -> 0
A18: 17 | B18: =INDEX(Задача2!$B$6:$K$6,1)&"-"&INDEX(Задача2!$B$6:$K$6,4)&"-"&INDEX(Задача2!$B$6:$K$6,6) -> 12-24-56 | C18: =INDEX(Задача2!$B$7:$K$7,1) -> 0 | D18: =INDEX(Задача2!$B$7:$K$7,4) -> 0 | E18: =INDEX(Задача2!$B$7:$K$7,6) -> 0 | F18: =(C18+D18+E18)/3 -> 0
A19: 18 | B19: =INDEX(Задача2!$B$6:$K$6,1)&"-"&INDEX(Задача2!$B$6:$K$6,4)&"-"&INDEX(Задача2!$B$6:$K$6,7) -> 12-24-64 | C19: =INDEX(Задача2!$B$7:$K$7,1) -> 0 | D19: =INDEX(Задача2!$B$7:$K$7,4) -> 0 | E19: =INDEX(Задача2!$B$7:$K$7,7) -> 0 | F19: =(C19+D19+E19)/3 -> 0
A20: 19 | B20: =INDEX(Задача2!$B$6:$K$6,1)&"-"&INDEX(Задача2!$B$6:$K$6,4)&"-"&INDEX(Задача2!$B$6:$K$6,8) -> 12-24-67 | C20: =INDEX(Задача2!$B$7:$K$7,1) -> 0 | D20: =INDEX(Задача2!$B$7:$K$7,4) -> 0 | E20: =INDEX(Задача2!$B$7:$K$7,8) -> 0 | F20: =(C20+D20+E20)/3 -> 0
A21: 20 | B21: =INDEX(Задача2!$B$6:$K$6,1)&"-"&INDEX(Задача2!$B$6:$K$6,4)&"-"&INDEX(Задача2!$B$6:$K$6,9) -> 12-24-71 | C21: =INDEX(Задача2!$B$7:$K$7,1) -> 0 | D21: =INDEX(Задача2!$B$7:$K$7,4) -> 0 | E21: =INDEX(Задача2!$B$7:$K$7,9) -> 0 | F21: =(C21+D21+E21)/3 -> 0
A22: 21 | B22: =INDEX(Задача2!$B$6:$K$6,1)&"-"&INDEX(Задача2!$B$6:$K$6,4)&"-"&INDEX(Задача2!$B$6:$K$6,10) -> 12-24-91 | C22: =INDEX(Задача2!$B$7:$K$7,1) -> 0 | D22: =INDEX(Задача2!$B$7:$K$7,4) -> 0 | E22: =INDEX(Задача2!$B$7:$K$7,10) -> 0 | F22: =(C22+D22+E22)/3 -> 0
A23: 22 | B23: =INDEX(Задача2!$B$6:$K$6,1)&"-"&INDEX(Задача2!$B$6:$K$6,5)&"-"&INDEX(Задача2!$B$6:$K$6,6) -> 12-32-56 | C23: =INDEX(Задача2!$B$7:$K$7,1) -> 0 | D23: =INDEX(Задача2!$B$7:$K$7,5) -> 0 | E23: =INDEX(Задача2!$B$7:$K$7,6) -> 0 | F23: =(C23+D23+E23)/3 -> 0
A24: 23 | B24: =INDEX(Задача2!$B$6:$K$6,1)&"-"&INDEX(Задача2!$B$6:$K$6,5)&"-"&INDEX(Задача2!$B$6:$K$6,7) -> 12-32-64 | C24: =INDEX(Задача2!$B$7:$K$7,1) -> 0 | D24: =INDEX(Задача2!$B$7:$K$7,5) -> 0 | E24: =INDEX(Задача2!$B$7:$K$7,7) -> 0 | F24: =(C24+D24+E24)/3 -> 0
A25: 24 | B25: =INDEX(Задача2!$B$6:$K$6,1)&"-"&INDEX(Задача2!$B$6:$K$6,5)&"-"&INDEX(Задача2!$B$6:$K$6,8) -> 12-32-67 | C25: =INDEX(Задача2!$B$7:$K$7,1) -> 0 | D25: =INDEX(Задача2!$B$7:$K$7,5) -> 0 | E25: =INDEX(Задача2!$B$7:$K$7,8) -> 0 | F25: =(C25+D25+E25)/3 -> 0
A26: 25 | B26: =INDEX(Задача2!$B$6:$K$6,1)&"-"&INDEX(Задача2!$B$6:$K$6,5)&"-"&INDEX(Задача2!$B$6:$K$6,9) -> 12-32-71 | C26: =INDEX(Задача2!$B$7:$K$7,1) -> 0 | D26: =INDEX(Задача2!$B$7:$K$7,5) -> 0 | E26: =INDEX(Задача2!$B$7:$K$7,9) -> 0 | F26: =(C26+D26+E26)/3 -> 0
A27: 26 | B27: =INDEX(Задача2!$B$6:$K$6,1)&"-"&INDEX(Задача2!$B$6:$K$6,5)&"-"&INDEX(Задача2!$B$6:$K$6,10) -> 12-32-91 | C27: =INDEX(Задача2!$B$7:$K$7,1) -> 0 | D27: =INDEX(Задача2!$B$7:$K$7,5) -> 0 | E27: =INDEX(Задача2!$B$7:$K$7,10) -> 0 | F27: =(C27+D27+E27)/3 -> 0
A28: 27 | B28: =INDEX(Задача2!$B$6:$K$6,1)&"-"&INDEX(Задача2!$B$6:$K$6,6)&"-"&INDEX(Задача2!$B$6:$K$6,7) -> 12-56-64 | C28: =INDEX(Задача2!$B$7:$K$7,1) -> 0 | D28: =INDEX(Задача2!$B$7:$K$7,6) -> 0 | E28: =INDEX(Задача2!$B$7:$K$7,7) -> 0 | F28: =(C28+D28+E28)/3 -> 0
A29: 28 | B29: =INDEX(Задача2!$B$6:$K$6,1)&"-"&INDEX(Задача2!$B$6:$K$6,6)&"-"&INDEX(Задача2!$B$6:$K$6,8) -> 12-56-67 | C29: =INDEX(Задача2!$B$7:$K$7,1) -> 0 | D29: =INDEX(Задача2!$B$7:$K$7,6) -> 0 | E29: =INDEX(Задача2!$B$7:$K$7,8) -> 0 | F29: =(C29+D29+E29)/3 -> 0
A30: 29 | B30: =INDEX(Задача2!$B$6:$K$6,1)&"-"&INDEX(Задача2!$B$6:$K$6,6)&"-"&INDEX(Задача2!$B$6:$K$6,9) -> 12-56-71 | C30: =INDEX(Задача2!$B$7:$K$7,1) -> 0 | D30: =INDEX(Задача2!$B$7:$K$7,6) -> 0 | E30: =INDEX(Задача2!$B$7:$K$7,9) -> 0 | F30: =(C30+D30+E30)/3 -> 0
A31: 30 | B31: =INDEX(Задача2!$B$6:$K$6,1)&"-"&INDEX(Задача2!$B$6:$K$6,6)&"-"&INDEX(Задача2!$B$6:$K$6,10) -> 12-56-91 | C31: =INDEX(Задача2!$B$7:$K$7,1) -> 0 | D31: =INDEX(Задача2!$B$7:$K$7,6) -> 0 | E31: =INDEX(Задача2!$B$7:$K$7,10) -> 0 | F31: =(C31+D31+E31)/3 -> 0
A32: 31 | B32: =INDEX(Задача2!$B$6:$K$6,1)&"-"&INDEX(Задача2!$B$6:$K$6,7)&"-"&INDEX(Задача2!$B$6:$K$6,8) -> 12-64-67 | C32: =INDEX(Задача2!$B$7:$K$7,1) -> 0 | D32: =INDEX(Задача2!$B$7:$K$7,7) -> 0 | E32: =INDEX(Задача2!$B$7:$K$7,8) -> 0 | F32: =(C32+D32+E32)/3 -> 0
A33: 32 | B33: =INDEX(Задача2!$B$6:$K$6,1)&"-"&INDEX(Задача2!$B$6:$K$6,7)&"-"&INDEX(Задача2!$B$6:$K$6,9) -> 12-64-71 | C33: =INDEX(Задача2!$B$7:$K$7,1) -> 0 | D33: =INDEX(Задача2!$B$7:$K$7,7) -> 0 | E33: =INDEX(Задача2!$B$7:$K$7,9) -> 0 | F33: =(C33+D33+E33)/3 -> 0
A34: 33 | B34: =INDEX(Задача2!$B$6:$K$6,1)&"-"&INDEX(Задача2!$B$6:$K$6,7)&"-"&INDEX(Задача2!$B$6:$K$6,10) -> 12-64-91 | C34: =INDEX(Задача2!$B$7:$K$7,1) -> 0 | D34: =INDEX(Задача2!$B$7:$K$7,7) -> 0 | E34: =INDEX(Задача2!$B$7:$K$7,10) -> 0 | F34: =(C34+D34+E34)/3 -> 0
A35: 34 | B35: =INDEX(Задача2!$B$6:$K$6,1)&"-"&INDEX(Задача2!$B$6:$K$6,8)&"-"&INDEX(Задача2!$B$6:$K$6,9) -> 12-67-71 | C35: =INDEX(Задача2!$B$7:$K$7,1) -> 0 | D35: =INDEX(Задача2!$B$7:$K$7,8) -> 0 | E35: =INDEX(Задача2!$B$7:$K$7,9) -> 0 | F35: =(C35+D35+E35)/3 -> 0
A36: 35 | B36: =INDEX(Задача2!$B$6:$K$6,1)&"-"&INDEX(Задача2!$B$6:$K$6,8)&"-"&INDEX(Задача2!$B$6:$K$6,10) -> 12-67-91 | C36: =INDEX(Задача2!$B$7:$K$7,1) -> 0 | D36: =INDEX(Задача2!$B$7:$K$7,8) -> 0 | E36: =INDEX(Задача2!$B$7:$K$7,10) -> 0 | F36: =(C36+D36+E36)/3 -> 0
A37: 36 | B37: =INDEX(Задача2!$B$6:$K$6,1)&"-"&INDEX(Задача2!$B$6:$K$6,9)&"-"&INDEX(Задача2!$B$6:$K$6,10) -> 12-71-91 | C37: =INDEX(Задача2!$B$7:$K$7,1) -> 0 | D37: =INDEX(Задача2!$B$7:$K$7,9) -> 0 | E37: =INDEX(Задача2!$B$7:$K$7,10) -> 0 | F37: =(C37+D37+E37)/3 -> 0
A38: 37 | B38: =INDEX(Задача2!$B$6:$K$6,2)&"-"&INDEX(Задача2!$B$6:$K$6,3)&"-"&INDEX(Задача2!$B$6:$K$6,4) -> 14-18-24 | C38: =INDEX(Задача2!$B$7:$K$7,2) -> 0 | D38: =INDEX(Задача2!$B$7:$K$7,3) -> 0 | E38: =INDEX(Задача2!$B$7:$K$7,4) -> 0 | F38: =(C38+D38+E38)/3 -> 0
A39: 38 | B39: =INDEX(Задача2!$B$6:$K$6,2)&"-"&INDEX(Задача2!$B$6:$K$6,3)&"-"&INDEX(Задача2!$B$6:$K$6,5) -> 14-18-32 | C39: =INDEX(Задача2!$B$7:$K$7,2) -> 0 | D39: =INDEX(Задача2!$B$7:$K$7,3) -> 0 | E39: =INDEX(Задача2!$B$7:$K$7,5) -> 0 | F39: =(C39+D39+E39)/3 -> 0
A40: 39 | B40: =INDEX(Задача2!$B$6:$K$6,2)&"-"&INDEX(Задача2!$B$6:$K$6,3)&"-"&INDEX(Задача2!$B$6:$K$6,6) -> 14-18-56 | C40: =INDEX(Задача2!$B$7:$K$7,2) -> 0 | D40: =INDEX(Задача2!$B$7:$K$7,3) -> 0 | E40: =INDEX(Задача2!$B$7:$K$7,6) -> 0 | F40: =(C40+D40+E40)/3 -> 0
...
