Workbook

Sheet Задача 1
A1: Вариант 1. Тальян Антон
A2: Задача 1. Отбор 10% предприятий из 100 методом прямой реализации (простая случайная выборка без возвращения)
A4: N = | B4: 100
A5: доля отбора | B5: 0.1
A6: n = | B6: =B4*B5 -> 10
A8: Таблица случайных чисел
B9: 1 | C9: 2 | D9: 3 | E9: 4 | F9: 5 | G9: 6 | H9: 7
A10: 1 | B10: 6955 | C10: 6141 | D10: 9951 | E10: 3439 | F10: 590 | G10: 8376 | H10: 5585
A11: 2 | B11: 4877 | C11: 2580 | D11: 6212 | E11: 1359 | F11: 1053 | G11: 8073 | H11: 2121
A12: 3 | B12: 4591 | C12: 5575 | D12: 7851 | E12: 884 | F12: 2869 | G12: 4514 | H12: 672
A13: 4 | B13: 9378 | C13: 2205 | D13: 4373 | E13: 9690 | F13: 4018 | G13: 9670 | H13: 5164
A14: 5 | B14: 1578 | C14: 247 | D14: 9108 | E14: 8830 | F14: 8485 | G14: 5948 | H14: 3325
A15: 6 | B15: 5597 | C15: 2216 | D15: 1203 | E15: 9897 | F15: 6086 | G15: 6916 | H15: 3135
A16: 7 | B16: 8773 | C16: 2443 | D16: 6686 | E16: 926 | F16: 9329 | G16: 8220 | H16: 865
A17: 8 | B17: 3173 | C17: 1019 | D17: 8089 | E17: 9283 | F17: 3592 | G17: 8447 | H17: 11
A18: 9 | B18: 802 | C18: 6442 | D18: 6426 | E18: 946 | F18: 9464 | G18: 4417 | H18: 2835
A19: 10 | B19: 3174 | C19: 7609 | D19: 4862 | E19: 8646 | F19: 4358 | G19: 493 | H19: 6623
A21: Начальный столбец (выбран случайно от 1 до 7): | G21: 7
A22: Читаем столбец сверху вниз, когда он кончается - следующий столбец. Берем две последние цифры числа (00 = 100), повторы пропускаем.
A24: № шага | B24: Случайное число | C24: Две последние цифры | D24: Результат | E24: В выборку
A25: 1 | B25: =H10 -> 5585 | C25: =IF(MOD(B25,100)=0,100,MOD(B25,100)) -> 85 | D25: =IF(COUNTIF(C$24:C24,C25)>0,"повтор, пропуск","отобрано") -> отобрано | E25: =IF(D25="отобрано",C25,"") -> 85
A26: 2 | B26: =H11 -> 2121 | C26: =IF(MOD(B26,100)=0,100,MOD(B26,100)) -> 21 | D26: =IF(COUNTIF(C$24:C25,C26)>0,"повтор, пропуск","отобрано") -> отобрано | E26: =IF(D26="отобрано",C26,"") -> 21
A27: 3 | B27: =H12 -> 672 | C27: =IF(MOD(B27,100)=0,100,MOD(B27,100)) -> 72 | D27: =IF(COUNTIF(C$24:C26,C27)>0,"повтор, пропуск","отобрано") -> отобрано | E27: =IF(D27="отобрано",C27,"") -> 72
A28: 4 | B28: =H13 -> 5164 | C28: =IF(MOD(B28,100)=0,100,MOD(B28,100)) -> 64 | D28: =IF(COUNTIF(C$24:C27,C28)>0,"повтор, пропуск","отобрано") -> отобрано | E28: =IF(D28="отобрано",C28,"") -> 64
A29: 5 | B29: =H14 -> 3325 | C29: =IF(MOD(B29,100)=0,100,MOD(B29,100)) -> 25 | D29: =IF(COUNTIF(C$24:C28,C29)>0,"повтор, пропуск","отобрано") -> отобрано | E29: =IF(D29="отобрано",C29,"") -> 25
A30: 6 | B30: =H15 -> 3135 | C30: =IF(MOD(B30,100)=0,100,MOD(B30,100)) -> 35 | D30: =IF(COUNTIF(C$24:C29,C30)>0,"повтор, пропуск","отобрано") -> отобрано | E30: =IF(D30="отобрано",C30,"") -> 35
A31: 7 | B31: =H16 -> 865 | C31: =IF(MOD(B31,100)=0,100,MOD(B31,100)) -> 65 | D31: =IF(COUNTIF(C$24:C30,C31)>0,"повтор, пропуск","отобрано") -> отобрано | E31: =IF(D31="отобрано",C31,"") -> 65
A32: 8 | B32: =H17 -> 11 | C32: =IF(MOD(B32,100)=0,100,MOD(B32,100)) -> 11 | D32: =IF(COUNTIF(C$24:C31,C32)>0,"повтор, пропуск","отобрано") -> отобрано | E32: =IF(D32="отобрано",C32,"") -> 11
A33: 9 | B33: =H18 -> 2835 | C33: =IF(MOD(B33,100)=0,100,MOD(B33,100)) -> 35 | D33: =IF(COUNTIF(C$24:C32,C33)>0,"повтор, пропуск","отобрано") -> повтор, пропуск | E33: =IF(D33="отобрано",C33,"")
A34: 10 | B34: =H19 -> 6623 | C34: =IF(MOD(B34,100)=0,100,MOD(B34,100)) -> 23 | D34: =IF(COUNTIF(C$24:C33,C34)>0,"повтор, пропуск","отобрано") -> отобрано | E34: =IF(D34="отобрано",C34,"") -> 23
A35: 11 | B35: =B10 -> 6955 | C35: =IF(MOD(B35,100)=0,100,MOD(B35,100)) -> 55 | D35: =IF(COUNTIF(C$24:C34,C35)>0,"повтор, пропуск","отобрано") -> отобрано | E35: =IF(D35="отобрано",C35,"") -> 55
A37: Выборка (по возрастанию):
A38: № п/п | B38: № предприятия
A39: 1 | B39: =SMALL($E$25:$E$35,A39) -> 11
A40: 2 | B40: =SMALL($E$25:$E$35,A40) -> 21
A41: 3 | B41: =SMALL($E$25:$E$35,A41) -> 23
A42: 4 | B42: =SMALL($E$25:$E$35,A42) -> 25
A43: 5 | B43: =SMALL($E$25:$E$35,A43) -> 35
A44: 6 | B44: =SMALL($E$25:$E$35,A44) -> 55
A45: 7 | B45: =SMALL($E$25:$E$35,A45) -> 64
...

Sheet Задача 2
A1: Задача 2 | H1: Все возможные выборки по 3 предприятия из 10
A2: Фамилия на букву Т - колонка 14 табл. 1 приложения 1 | H2: № | I2: № п/п 1 | J2: № п/п 2 | K2: № п/п 3 | L2: Предприятия | M2: Средняя
A3: Генеральная совокупность - 10 предприятий из задачи 1 (N = 10), отбираем n = 3 без повторения | H3: 1 | I3: 1 | J3: 2 | K3: 3 | L3: =INDEX($B$6:$B$15,I3)&", "&INDEX($B$6:$B$15,J3)&", "&INDEX($B$6:$B$15,K3) -> 11, 21, 23 | M3: =(INDEX($C$6:$C$15,I3)+INDEX($C$6:$C$15,J3)+INDEX($C$6:$C$15,K3))/3 -> 0
H4: 2 | I4: 1 | J4: 2 | K4: 4 | L4: =INDEX($B$6:$B$15,I4)&", "&INDEX($B$6:$B$15,J4)&", "&INDEX($B$6:$B$15,K4) -> 11, 21, 25 | M4: =(INDEX($C$6:$C$15,I4)+INDEX($C$6:$C$15,J4)+INDEX($C$6:$C$15,K4))/3 -> 0
A5: № п/п | B5: № предприятия | C5: Значение (колонка 14) | H5: 3 | I5: 1 | J5: 2 | K5: 5 | L5: =INDEX($B$6:$B$15,I5)&", "&INDEX($B$6:$B$15,J5)&", "&INDEX($B$6:$B$15,K5) -> 11, 21, 35 | M5: =(INDEX($C$6:$C$15,I5)+INDEX($C$6:$C$15,J5)+INDEX($C$6:$C$15,K5))/3 -> 0
A6: 1 | B6: ='Задача 1'!B39 -> 11 | D6: <- значения из приложения 1 | H6: 4 | I6: 1 | J6: 2 | K6: 6 | L6: =INDEX($B$6:$B$15,I6)&", "&INDEX($B$6:$B$15,J6)&", "&INDEX($B$6:$B$15,K6) -> 11, 21, 55 | M6: =(INDEX($C$6:$C$15,I6)+INDEX($C$6:$C$15,J6)+INDEX($C$6:$C$15,K6))/3 -> 0
A7: 2 | B7: ='Задача 1'!B40 -> 21 | H7: 5 | I7: 1 | J7: 2 | K7: 7 | L7: =INDEX($B$6:$B$15,I7)&", "&INDEX($B$6:$B$15,J7)&", "&INDEX($B$6:$B$15,K7) -> 11, 21, 64 | M7: =(INDEX($C$6:$C$15,I7)+INDEX($C$6:$C$15,J7)+INDEX($C$6:$C$15,K7))/3 -> 0
A8: 3 | B8: ='Задача 1'!B41 -> 23 | H8: 6 | I8: 1 | J8: 2 | K8: 8 | L8: =INDEX($B$6:$B$15,I8)&", "&INDEX($B$6:$B$15,J8)&", "&INDEX($B$6:$B$15,K8) -> 11, 21, 65 | M8: =(INDEX($C$6:$C$15,I8)+INDEX($C$6:$C$15,J8)+INDEX($C$6:$C$15,K8))/3 -> 0
A9: 4 | B9: ='Задача 1'!B42 -> 25 | H9: 7 | I9: 1 | J9: 2 | K9: 9 | L9: =INDEX($B$6:$B$15,I9)&", "&INDEX($B$6:$B$15,J9)&", "&INDEX($B$6:$B$15,K9) -> 11, 21, 72 | M9: =(INDEX($C$6:$C$15,I9)+INDEX($C$6:$C$15,J9)+INDEX($C$6:$C$15,K9))/3 -> 0
A10: 5 | B10: ='Задача 1'!B43 -> 35 | H10: 8 | I10: 1 | J10: 2 | K10: 10 | L10: =INDEX($B$6:$B$15,I10)&", "&INDEX($B$6:$B$15,J10)&", "&INDEX($B$6:$B$15,K10) -> 11, 21, 85 | M10: =(INDEX($C$6:$C$15,I10)+INDEX($C$6:$C$15,J10)+INDEX($C$6:$C$15,K10))/3 -> 0
A11: 6 | B11: ='Задача 1'!B44 -> 55 | H11: 9 | I11: 1 | J11: 3 | K11: 4 | L11: =INDEX($B$6:$B$15,I11)&", "&INDEX($B$6:$B$15,J11)&", "&INDEX($B$6:$B$15,K11) -> 11, 23, 25 | M11: =(INDEX($C$6:$C$15,I11)+INDEX($C$6:$C$15,J11)+INDEX($C$6:$C$15,K11))/3 -> 0
A12: 7 | B12: ='Задача 1'!B45 -> 64 | H12: 10 | I12: 1 | J12: 3 | K12: 5 | L12: =INDEX($B$6:$B$15,I12)&", "&INDEX($B$6:$B$15,J12)&", "&INDEX($B$6:$B$15,K12) -> 11, 23, 35 | M12: =(INDEX($C$6:$C$15,I12)+INDEX($C$6:$C$15,J12)+INDEX($C$6:$C$15,K12))/3 -> 0
A13: 8 | B13: ='Задача 1'!B46 -> 65 | H13: 11 | I13: 1 | J13: 3 | K13: 6 | L13: =INDEX($B$6:$B$15,I13)&", "&INDEX($B$6:$B$15,J13)&", "&INDEX($B$6:$B$15,K13) -> 11, 23, 55 | M13: =(INDEX($C$6:$C$15,I13)+INDEX($C$6:$C$15,J13)+INDEX($C$6:$C$15,K13))/3 -> 0
A14: 9 | B14: ='Задача 1'!B47 -> 72 | H14: 12 | I14: 1 | J14: 3 | K14: 7 | L14: =INDEX($B$6:$B$15,I14)&", "&INDEX($B$6:$B$15,J14)&", "&INDEX($B$6:$B$15,K14) -> 11, 23, 64 | M14: =(INDEX($C$6:$C$15,I14)+INDEX($C$6:$C$15,J14)+INDEX($C$6:$C$15,K14))/3 -> 0
A15: 10 | B15: ='Задача 1'!B48 -> 85 | H15: 13 | I15: 1 | J15: 3 | K15: 8 | L15: =INDEX($B$6:$B$15,I15)&", "&INDEX($B$6:$B$15,J15)&", "&INDEX($B$6:$B$15,K15) -> 11, 23, 65 | M15: =(INDEX($C$6:$C$15,I15)+INDEX($C$6:$C$15,J15)+INDEX($C$6:$C$15,K15))/3 -> 0
B16: Сумма | C16: =SUM(C6:C15) -> 0 | H16: 14 | I16: 1 | J16: 3 | K16: 9 | L16: =INDEX($B$6:$B$15,I16)&", "&INDEX($B$6:$B$15,J16)&", "&INDEX($B$6:$B$15,K16) -> 11, 23, 72 | M16: =(INDEX($C$6:$C$15,I16)+INDEX($C$6:$C$15,J16)+INDEX($C$6:$C$15,K16))/3 -> 0
B17: Хср | C17: =C16/10 -> 0 | H17: 15 | I17: 1 | J17: 3 | K17: 10 | L17: =INDEX($B$6:$B$15,I17)&", "&INDEX($B$6:$B$15,J17)&", "&INDEX($B$6:$B$15,K17) -> 11, 23, 85 | M17: =(INDEX($C$6:$C$15,I17)+INDEX($C$6:$C$15,J17)+INDEX($C$6:$C$15,K17))/3 -> 0
H18: 16 | I18: 1 | J18: 4 | K18: 5 | L18: =INDEX($B$6:$B$15,I18)&", "&INDEX($B$6:$B$15,J18)&", "&INDEX($B$6:$B$15,K18) -> 11, 25, 35 | M18: =(INDEX($C$6:$C$15,I18)+INDEX($C$6:$C$15,J18)+INDEX($C$6:$C$15,K18))/3 -> 0
A19: Количество сочетаний C(10;3) = | E19: =COMBIN(10,3) -> 120 | H19: 17 | I19: 1 | J19: 4 | K19: 6 | L19: =INDEX($B$6:$B$15,I19)&", "&INDEX($B$6:$B$15,J19)&", "&INDEX($B$6:$B$15,K19) -> 11, 25, 55 | M19: =(INDEX($C$6:$C$15,I19)+INDEX($C$6:$C$15,J19)+INDEX($C$6:$C$15,K19))/3 -> 0
A20: то же через факториалы 10!/(3!*7!) = | E20: =FACT(10)/(FACT(3)*FACT(7)) -> 120 | H20: 18 | I20: 1 | J20: 4 | K20: 7 | L20: =INDEX($B$6:$B$15,I20)&", "&INDEX($B$6:$B$15,J20)&", "&INDEX($B$6:$B$15,K20) -> 11, 25, 64 | M20: =(INDEX($C$6:$C$15,I20)+INDEX($C$6:$C$15,J20)+INDEX($C$6:$C$15,K20))/3 -> 0
H21: 19 | I21: 1 | J21: 4 | K21: 8 | L21: =INDEX($B$6:$B$15,I21)&", "&INDEX($B$6:$B$15,J21)&", "&INDEX($B$6:$B$15,K21) -> 11, 25, 65 | M21: =(INDEX($C$6:$C$15,I21)+INDEX($C$6:$C$15,J21)+INDEX($C$6:$C$15,K21))/3 -> 0
A22: Отбор 3 предприятий: продолжаем таблицу случайных чисел (1 столбец, 2 строка), последняя цифра = № п/п (0 = 10) | H22: 20 | I22: 1 | J22: 4 | K22: 9 | L22: =INDEX($B$6:$B$15,I22)&", "&INDEX($B$6:$B$15,J22)&", "&INDEX($B$6:$B$15,K22) -> 11, 25, 72 | M22: =(INDEX($C$6:$C$15,I22)+INDEX($C$6:$C$15,J22)+INDEX($C$6:$C$15,K22))/3 -> 0
A23: Случайное число | B23: Последняя цифра | C23: № п/п | D23: № предприятия | E23: Значение | H23: 21 | I23: 1 | J23: 4 | K23: 10 | L23: =INDEX($B$6:$B$15,I23)&", "&INDEX($B$6:$B$15,J23)&", "&INDEX($B$6:$B$15,K23) -> 11, 25, 85 | M23: =(INDEX($C$6:$C$15,I23)+INDEX($C$6:$C$15,J23)+INDEX($C$6:$C$15,K23))/3 -> 0
A24: ='Задача 1'!B11 -> 4877 | B24: =MOD(A24,10) -> 7 | C24: =IF(B24=0,10,B24) -> 7 | D24: =INDEX($B$6:$B$15,C24) -> 64 | E24: =INDEX($C$6:$C$15,C24) -> 0 | H24: 22 | I24: 1 | J24: 5 | K24: 6 | L24: =INDEX($B$6:$B$15,I24)&", "&INDEX($B$6:$B$15,J24)&", "&INDEX($B$6:$B$15,K24) -> 11, 35, 55 | M24: =(INDEX($C$6:$C$15,I24)+INDEX($C$6:$C$15,J24)+INDEX($C$6:$C$15,K24))/3 -> 0
A25: ='Задача 1'!B12 -> 4591 | B25: =MOD(A25,10) -> 1 | C25: =IF(B25=0,10,B25) -> 1 | D25: =INDEX($B$6:$B$15,C25) -> 11 | E25: =INDEX($C$6:$C$15,C25) -> 0 | H25: 23 | I25: 1 | J25: 5 | K25: 7 | L25: =INDEX($B$6:$B$15,I25)&", "&INDEX($B$6:$B$15,J25)&", "&INDEX($B$6:$B$15,K25) -> 11, 35, 64 | M25: =(INDEX($C$6:$C$15,I25)+INDEX($C$6:$C$15,J25)+INDEX($C$6:$C$15,K25))/3 -> 0
A26: ='Задача 1'!B13 -> 9378 | B26: =MOD(A26,10) -> 8 | C26: =IF(B26=0,10,B26) -> 8 | D26: =INDEX($B$6:$B$15,C26) -> 65 | E26: =INDEX($C$6:$C$15,C26) -> 0 | H26: 24 | I26: 1 | J26: 5 | K26: 8 | L26: =INDEX($B$6:$B$15,I26)&", "&INDEX($B$6:$B$15,J26)&", "&INDEX($B$6:$B$15,K26) -> 11, 35, 65 | M26: =(INDEX($C$6:$C$15,I26)+INDEX($C$6:$C$15,J26)+INDEX($C$6:$C$15,K26))/3 -> 0
D27: Сумма | E27: =SUM(E24:E26) -> 0 | H27: 25 | I27: 1 | J27: 5 | K27: 9 | L27: =INDEX($B$6:$B$15,I27)&", "&INDEX($B$6:$B$15,J27)&", "&INDEX($B$6:$B$15,K27) -> 11, 35, 72 | M27: =(INDEX($C$6:$C$15,I27)+INDEX($C$6:$C$15,J27)+INDEX($C$6:$C$15,K27))/3 -> 0
D28: хср | E28: =E27/3 -> 0 | H28: 26 | I28: 1 | J28: 5 | K28: 10 | L28: =INDEX($B$6:$B$15,I28)&", "&INDEX($B$6:$B$15,J28)&", "&INDEX($B$6:$B$15,K28) -> 11, 35, 85 | M28: =(INDEX($C$6:$C$15,I28)+INDEX($C$6:$C$15,J28)+INDEX($C$6:$C$15,K28))/3 -> 0
D29: хср - Хср | E29: =E28-C17 -> 0 | H29: 27 | I29: 1 | J29: 6 | K29: 7 | L29: =INDEX($B$6:$B$15,I29)&", "&INDEX($B$6:$B$15,J29)&", "&INDEX($B$6:$B$15,K29) -> 11, 55, 64 | M29: =(INDEX($C$6:$C$15,I29)+INDEX($C$6:$C$15,J29)+INDEX($C$6:$C$15,K29))/3 -> 0
H30: 28 | I30: 1 | J30: 6 | K30: 8 | L30: =INDEX($B$6:$B$15,I30)&", "&INDEX($B$6:$B$15,J30)&", "&INDEX($B$6:$B$15,K30) -> 11, 55, 65 | M30: =(INDEX($C$6:$C$15,I30)+INDEX($C$6:$C$15,J30)+INDEX($C$6:$C$15,K30))/3 -> 0
A31: Проверка на несмещенность (все 120 выборок в столбцах H:M) | H31: 29 | I31: 1 | J31: 6 | K31: 9 | L31: =INDEX($B$6:$B$15,I31)&", "&INDEX($B$6:$B$15,J31)&", "&INDEX($B$6:$B$15,K31) -> 11, 55, 72 | M31: =(INDEX($C$6:$C$15,I31)+INDEX($C$6:$C$15,J31)+INDEX($C$6:$C$15,K31))/3 -> 0
A32: Среднее из 120 выборочных средних M(хср) = | E32: =AVERAGE(M3:M122) -> 0 | H32: 30 | I32: 1 | J32: 6 | K32: 10 | L32: =INDEX($B$6:$B$15,I32)&", "&INDEX($B$6:$B$15,J32)&", "&INDEX($B$6:$B$15,K32) -> 11, 55, 85 | M32: =(INDEX($C$6:$C$15,I32)+INDEX($C$6:$C$15,J32)+INDEX($C$6:$C$15,K32))/3 -> 0
A33: Генеральная средняя Хср = | E33: =C17 -> 0 | H33: 31 | I33: 1 | J33: 7 | K33: 8 | L33: =INDEX($B$6:$B$15,I33)&", "&INDEX($B$6:$B$15,J33)&", "&INDEX($B$6:$B$15,K33) -> 11, 64, 65 | M33: =(INDEX($C$6:$C$15,I33)+INDEX($C$6:$C$15,J33)+INDEX($C$6:$C$15,K33))/3 -> 0
A34: Каждое предприятие входит в C(9;2) = | E34: =COMBIN(9,2) -> 36 | H34: 32 | I34: 1 | J34: 7 | K34: 9 | L34: =INDEX($B$6:$B$15,I34)&", "&INDEX($B$6:$B$15,J34)&", "&INDEX($B$6:$B$15,K34) -> 11, 64, 72 | M34: =(INDEX($C$6:$C$15,I34)+INDEX($C$6:$C$15,J34)+INDEX($C$6:$C$15,K34))/3 -> 0
A35: Средние выборок: от | C35: =MIN(M3:M122) -> 0 | D35: до | E35: =MAX(M3:M122) -> 0 | H35: 33 | I35: 1 | J35: 7 | K35: 10 | L35: =INDEX($B$6:$B$15,I35)&", "&INDEX($B$6:$B$15,J35)&", "&INDEX($B$6:$B$15,K35) -> 11, 64, 85 | M35: =(INDEX($C$6:$C$15,I35)+INDEX($C$6:$C$15,J35)+INDEX($C$6:$C$15,K35))/3 -> 0
A36: Вывод: | B36: =IF(COUNT(C6:C15)<10,"нужно вписать значения из приложения 1",IF(ABS(E32-E33)<0.000001,"M(хср) = Хср, значит выборочная средняя - несмещенная оценка","не совпадает")) -> нужно вписать значения из приложения 1 | H36: 34 | I36: 1 | J36: 8 | K36: 9 | L36: =INDEX($B$6:$B$15,I36)&", "&INDEX($B$6:$B$15,J36)&", "&INDEX($B$6:$B$15,K36) -> 11, 65, 72 | M36: =(INDEX($C$6:$C$15,I36)+INDEX($C$6:$C$15,J36)+INDEX($C$6:$C$15,K36))/3 -> 0
H37: 35 | I37: 1 | J37: 8 | K37: 10 | L37: =INDEX($B$6:$B$15,I37)&", "&INDEX($B$6:$B$15,J37)&", "&INDEX($B$6:$B$15,K37) -> 11, 65, 85 | M37: =(INDEX($C$6:$C$15,I37)+INDEX($C$6:$C$15,J37)+INDEX($C$6:$C$15,K37))/3 -> 0
H38: 36 | I38: 1 | J38: 9 | K38: 10 | L38: =INDEX($B$6:$B$15,I38)&", "&INDEX($B$6:$B$15,J38)&", "&INDEX($B$6:$B$15,K38) -> 11, 72, 85 | M38: =(INDEX($C$6:$C$15,I38)+INDEX($C$6:$C$15,J38)+INDEX($C$6:$C$15,K38))/3 -> 0
H39: 37 | I39: 2 | J39: 3 | K39: 4 | L39: =INDEX($B$6:$B$15,I39)&", "&INDEX($B$6:$B$15,J39)&", "&INDEX($B$6:$B$15,K39) -> 21, 23, 25 | M39: =(INDEX($C$6:$C$15,I39)+INDEX($C$6:$C$15,J39)+INDEX($C$6:$C$15,K39))/3 -> 0
H40: 38 | I40: 2 | J40: 3 | K40: 5 | L40: =INDEX($B$6:$B$15,I40)&", "&INDEX($B$6:$B$15,J40)&", "&INDEX($B$6:$B$15,K40) -> 21, 23, 35 | M40: =(INDEX($C$6:$C$15,I40)+INDEX($C$6:$C$15,J40)+INDEX($C$6:$C$15,K40))/3 -> 0
...
