Workbook

Sheet Задача 1
A1: Тальян Антон, вариант 1
A3: Задача 1
A4: N | B4: 100
A5: n | B5: =B4*10% -> 10
A7: 1 | B7: 2 | C7: 3 | D7: 4 | E7: 5 | F7: 6 | G7: 7
A8: 6955 | B8: 6141 | C8: 9951 | D8: 3439 | E8: 590 | F8: 8376 | G8: 5585
A9: 4877 | B9: 2580 | C9: 6212 | D9: 1359 | E9: 1053 | F9: 8073 | G9: 2121
A10: 4591 | B10: 5575 | C10: 7851 | D10: 884 | E10: 2869 | F10: 4514 | G10: 672
A11: 9378 | B11: 2205 | C11: 4373 | D11: 9690 | E11: 4018 | F11: 9670 | G11: 5164
A12: 1578 | B12: 247 | C12: 9108 | D12: 8830 | E12: 8485 | F12: 5948 | G12: 3325
A13: 5597 | B13: 2216 | C13: 1203 | D13: 9897 | E13: 6086 | F13: 6916 | G13: 3135
A14: 8773 | B14: 2443 | C14: 6686 | D14: 926 | E14: 9329 | F14: 8220 | G14: 865
A15: 3173 | B15: 1019 | C15: 8089 | D15: 9283 | E15: 3592 | F15: 8447 | G15: 11
A16: 802 | B16: 6442 | C16: 6426 | D16: 946 | E16: 9464 | F16: 4417 | G16: 2835
A17: 3174 | B17: 7609 | C17: 4862 | D17: 8646 | E17: 4358 | F17: 493 | G17: 6623
A19: старт | B19: 7
A21: число | B21: номер | C21: повтор | D21: в выборку
A22: =G8 -> 5585 | B22: =IF(MOD(A22,100)=0,100,MOD(A22,100)) -> 85 | C22: =IF(COUNTIF(B$21:B21,B22)>0,"повтор","") | D22: =IF(C22="",B22,"") -> 85
A23: =G9 -> 2121 | B23: =IF(MOD(A23,100)=0,100,MOD(A23,100)) -> 21 | C23: =IF(COUNTIF(B$21:B22,B23)>0,"повтор","") | D23: =IF(C23="",B23,"") -> 21
A24: =G10 -> 672 | B24: =IF(MOD(A24,100)=0,100,MOD(A24,100)) -> 72 | C24: =IF(COUNTIF(B$21:B23,B24)>0,"повтор","") | D24: =IF(C24="",B24,"") -> 72
A25: =G11 -> 5164 | B25: =IF(MOD(A25,100)=0,100,MOD(A25,100)) -> 64 | C25: =IF(COUNTIF(B$21:B24,B25)>0,"повтор","") | D25: =IF(C25="",B25,"") -> 64
A26: =G12 -> 3325 | B26: =IF(MOD(A26,100)=0,100,MOD(A26,100)) -> 25 | C26: =IF(COUNTIF(B$21:B25,B26)>0,"повтор","") | D26: =IF(C26="",B26,"") -> 25
A27: =G13 -> 3135 | B27: =IF(MOD(A27,100)=0,100,MOD(A27,100)) -> 35 | C27: =IF(COUNTIF(B$21:B26,B27)>0,"повтор","") | D27: =IF(C27="",B27,"") -> 35
A28: =G14 -> 865 | B28: =IF(MOD(A28,100)=0,100,MOD(A28,100)) -> 65 | C28: =IF(COUNTIF(B$21:B27,B28)>0,"повтор","") | D28: =IF(C28="",B28,"") -> 65
A29: =G15 -> 11 | B29: =IF(MOD(A29,100)=0,100,MOD(A29,100)) -> 11 | C29: =IF(COUNTIF(B$21:B28,B29)>0,"повтор","") | D29: =IF(C29="",B29,"") -> 11
A30: =G16 -> 2835 | B30: =IF(MOD(A30,100)=0,100,MOD(A30,100)) -> 35 | C30: =IF(COUNTIF(B$21:B29,B30)>0,"повтор","") -> повтор | D30: =IF(C30="",B30,"")
A31: =G17 -> 6623 | B31: =IF(MOD(A31,100)=0,100,MOD(A31,100)) -> 23 | C31: =IF(COUNTIF(B$21:B30,B31)>0,"повтор","") | D31: =IF(C31="",B31,"") -> 23
A32: =A8 -> 6955 | B32: =IF(MOD(A32,100)=0,100,MOD(A32,100)) -> 55 | C32: =IF(COUNTIF(B$21:B31,B32)>0,"повтор","") | D32: =IF(C32="",B32,"") -> 55
A34: выборка | B34: =SMALL($D$22:$D$32,1) -> 11 | C34: =SMALL($D$22:$D$32,2) -> 21 | D34: =SMALL($D$22:$D$32,3) -> 23 | E34: =SMALL($D$22:$D$32,4) -> 25 | F34: =SMALL($D$22:$D$32,5) -> 35 | G34: =SMALL($D$22:$D$32,6) -> 55 | H34: =SMALL($D$22:$D$32,7) -> 64 | I34: =SMALL($D$22:$D$32,8) -> 65 | J34: =SMALL($D$22:$D$32,9) -> 72 | K34: =SMALL($D$22:$D$32,10) -> 85

Sheet Задача 2
A1: Задача 2 | M1: выборки | N1: средняя
A2: колонка 14 - прибыль от реализации продукции, млн руб. | M2: =INDEX($B$4:$K$4,1)&", "&INDEX($B$4:$K$4,2)&", "&INDEX($B$4:$K$4,3) -> 11, 21, 23 | N2: =(INDEX($B$5:$K$5,1)+INDEX($B$5:$K$5,2)+INDEX($B$5:$K$5,3))/3 -> 2.81
M3: =INDEX($B$4:$K$4,1)&", "&INDEX($B$4:$K$4,2)&", "&INDEX($B$4:$K$4,4) -> 11, 21, 25 | N3: =(INDEX($B$5:$K$5,1)+INDEX($B$5:$K$5,2)+INDEX($B$5:$K$5,4))/3 -> 1.9866667
A4: предприятие | B4: ='Задача 1'!B34 -> 11 | C4: ='Задача 1'!C34 -> 21 | D4: ='Задача 1'!D34 -> 23 | E4: ='Задача 1'!E34 -> 25 | F4: ='Задача 1'!F34 -> 35 | G4: ='Задача 1'!G34 -> 55 | H4: ='Задача 1'!H34 -> 64 | I4: ='Задача 1'!I34 -> 65 | ... K4: ='Задача 1'!K34 -> 85 | M4: =INDEX($B$4:$K$4,1)&", "&INDEX($B$4:$K$4,2)&", "&INDEX($B$4:$K$4,5) -> 11, 21, 35 | N4: =(INDEX($B$5:$K$5,1)+INDEX($B$5:$K$5,2)+INDEX($B$5:$K$5,5))/3 -> 1.67
A5: значение | B5: 1.09 | C5: 2.76 | D5: 4.58 | E5: 2.11 | F5: 1.16 | G5: 3.09 | H5: 2.63 | I5: 2.17 | J5: 2.15 | K5: 2.11 | M5: =INDEX($B$4:$K$4,1)&", "&INDEX($B$4:$K$4,2)&", "&INDEX($B$4:$K$4,6) -> 11, 21, 55 | N5: =(INDEX($B$5:$K$5,1)+INDEX($B$5:$K$5,2)+INDEX($B$5:$K$5,6))/3 -> 2.3133333
M6: =INDEX($B$4:$K$4,1)&", "&INDEX($B$4:$K$4,2)&", "&INDEX($B$4:$K$4,7) -> 11, 21, 64 | N6: =(INDEX($B$5:$K$5,1)+INDEX($B$5:$K$5,2)+INDEX($B$5:$K$5,7))/3 -> 2.16
A7: сумма | B7: =SUM(B5:K5) -> 23.85 | M7: =INDEX($B$4:$K$4,1)&", "&INDEX($B$4:$K$4,2)&", "&INDEX($B$4:$K$4,8) -> 11, 21, 65 | N7: =(INDEX($B$5:$K$5,1)+INDEX($B$5:$K$5,2)+INDEX($B$5:$K$5,8))/3 -> 2.0066667
A8: Хср | B8: =B7/10 -> 2.385 | M8: =INDEX($B$4:$K$4,1)&", "&INDEX($B$4:$K$4,2)&", "&INDEX($B$4:$K$4,9) -> 11, 21, 72 | N8: =(INDEX($B$5:$K$5,1)+INDEX($B$5:$K$5,2)+INDEX($B$5:$K$5,9))/3 -> 2
A9: сочетаний | B9: =COMBIN(10,3) -> 120 | M9: =INDEX($B$4:$K$4,1)&", "&INDEX($B$4:$K$4,2)&", "&INDEX($B$4:$K$4,10) -> 11, 21, 85 | N9: =(INDEX($B$5:$K$5,1)+INDEX($B$5:$K$5,2)+INDEX($B$5:$K$5,10))/3 -> 1.9866667
M10: =INDEX($B$4:$K$4,1)&", "&INDEX($B$4:$K$4,3)&", "&INDEX($B$4:$K$4,4) -> 11, 23, 25 | N10: =(INDEX($B$5:$K$5,1)+INDEX($B$5:$K$5,3)+INDEX($B$5:$K$5,4))/3 -> 2.5933333
A11: число | B11: цифра | C11: № п/п | D11: предприятие | E11: значение | M11: =INDEX($B$4:$K$4,1)&", "&INDEX($B$4:$K$4,3)&", "&INDEX($B$4:$K$4,5) -> 11, 23, 35 | N11: =(INDEX($B$5:$K$5,1)+INDEX($B$5:$K$5,3)+INDEX($B$5:$K$5,5))/3 -> 2.2766667
A12: ='Задача 1'!A9 -> 4877 | B12: =MOD(A12,10) -> 7 | C12: =IF(B12=0,10,B12) -> 7 | D12: =INDEX($B$4:$K$4,C12) -> 64 | E12: =INDEX($B$5:$K$5,C12) -> 2.63 | M12: =INDEX($B$4:$K$4,1)&", "&INDEX($B$4:$K$4,3)&", "&INDEX($B$4:$K$4,6) -> 11, 23, 55 | N12: =(INDEX($B$5:$K$5,1)+INDEX($B$5:$K$5,3)+INDEX($B$5:$K$5,6))/3 -> 2.92
A13: ='Задача 1'!A10 -> 4591 | B13: =MOD(A13,10) -> 1 | C13: =IF(B13=0,10,B13) -> 1 | D13: =INDEX($B$4:$K$4,C13) -> 11 | E13: =INDEX($B$5:$K$5,C13) -> 1.09 | M13: =INDEX($B$4:$K$4,1)&", "&INDEX($B$4:$K$4,3)&", "&INDEX($B$4:$K$4,7) -> 11, 23, 64 | N13: =(INDEX($B$5:$K$5,1)+INDEX($B$5:$K$5,3)+INDEX($B$5:$K$5,7))/3 -> 2.7666667
A14: ='Задача 1'!A11 -> 9378 | B14: =MOD(A14,10) -> 8 | C14: =IF(B14=0,10,B14) -> 8 | D14: =INDEX($B$4:$K$4,C14) -> 65 | E14: =INDEX($B$5:$K$5,C14) -> 2.17 | M14: =INDEX($B$4:$K$4,1)&", "&INDEX($B$4:$K$4,3)&", "&INDEX($B$4:$K$4,8) -> 11, 23, 65 | N14: =(INDEX($B$5:$K$5,1)+INDEX($B$5:$K$5,3)+INDEX($B$5:$K$5,8))/3 -> 2.6133333
M15: =INDEX($B$4:$K$4,1)&", "&INDEX($B$4:$K$4,3)&", "&INDEX($B$4:$K$4,9) -> 11, 23, 72 | N15: =(INDEX($B$5:$K$5,1)+INDEX($B$5:$K$5,3)+INDEX($B$5:$K$5,9))/3 -> 2.6066667
A16: хср | B16: =SUM(E12:E14)/3 -> 1.9633333 | M16: =INDEX($B$4:$K$4,1)&", "&INDEX($B$4:$K$4,3)&", "&INDEX($B$4:$K$4,10) -> 11, 23, 85 | N16: =(INDEX($B$5:$K$5,1)+INDEX($B$5:$K$5,3)+INDEX($B$5:$K$5,10))/3 -> 2.5933333
A17: хср - Хср | B17: =B16-B8 -> -0.42166667 | M17: =INDEX($B$4:$K$4,1)&", "&INDEX($B$4:$K$4,4)&", "&INDEX($B$4:$K$4,5) -> 11, 25, 35 | N17: =(INDEX($B$5:$K$5,1)+INDEX($B$5:$K$5,4)+INDEX($B$5:$K$5,5))/3 -> 1.4533333
M18: =INDEX($B$4:$K$4,1)&", "&INDEX($B$4:$K$4,4)&", "&INDEX($B$4:$K$4,6) -> 11, 25, 55 | N18: =(INDEX($B$5:$K$5,1)+INDEX($B$5:$K$5,4)+INDEX($B$5:$K$5,6))/3 -> 2.0966667
A19: M(хср) | B19: =AVERAGE(N2:N121) -> 2.385 | M19: =INDEX($B$4:$K$4,1)&", "&INDEX($B$4:$K$4,4)&", "&INDEX($B$4:$K$4,7) -> 11, 25, 64 | N19: =(INDEX($B$5:$K$5,1)+INDEX($B$5:$K$5,4)+INDEX($B$5:$K$5,7))/3 -> 1.9433333
A20: =IF(COUNT(B5:K5)<10,"впиши значения из приложения 1",IF(ABS(B19-B8)<0.000001,"M(хср) = Хср, оценка несмещенная","не равны")) -> M(хср) = Хср, оценка несмещенная | M20: =INDEX($B$4:$K$4,1)&", "&INDEX($B$4:$K$4,4)&", "&INDEX($B$4:$K$4,8) -> 11, 25, 65 | N20: =(INDEX($B$5:$K$5,1)+INDEX($B$5:$K$5,4)+INDEX($B$5:$K$5,8))/3 -> 1.79
M21: =INDEX($B$4:$K$4,1)&", "&INDEX($B$4:$K$4,4)&", "&INDEX($B$4:$K$4,9) -> 11, 25, 72 | N21: =(INDEX($B$5:$K$5,1)+INDEX($B$5:$K$5,4)+INDEX($B$5:$K$5,9))/3 -> 1.7833333
M22: =INDEX($B$4:$K$4,1)&", "&INDEX($B$4:$K$4,4)&", "&INDEX($B$4:$K$4,10) -> 11, 25, 85 | N22: =(INDEX($B$5:$K$5,1)+INDEX($B$5:$K$5,4)+INDEX($B$5:$K$5,10))/3 -> 1.77
M23: =INDEX($B$4:$K$4,1)&", "&INDEX($B$4:$K$4,5)&", "&INDEX($B$4:$K$4,6) -> 11, 35, 55 | N23: =(INDEX($B$5:$K$5,1)+INDEX($B$5:$K$5,5)+INDEX($B$5:$K$5,6))/3 -> 1.78
M24: =INDEX($B$4:$K$4,1)&", "&INDEX($B$4:$K$4,5)&", "&INDEX($B$4:$K$4,7) -> 11, 35, 64 | N24: =(INDEX($B$5:$K$5,1)+INDEX($B$5:$K$5,5)+INDEX($B$5:$K$5,7))/3 -> 1.6266667
M25: =INDEX($B$4:$K$4,1)&", "&INDEX($B$4:$K$4,5)&", "&INDEX($B$4:$K$4,8) -> 11, 35, 65 | N25: =(INDEX($B$5:$K$5,1)+INDEX($B$5:$K$5,5)+INDEX($B$5:$K$5,8))/3 -> 1.4733333
M26: =INDEX($B$4:$K$4,1)&", "&INDEX($B$4:$K$4,5)&", "&INDEX($B$4:$K$4,9) -> 11, 35, 72 | N26: =(INDEX($B$5:$K$5,1)+INDEX($B$5:$K$5,5)+INDEX($B$5:$K$5,9))/3 -> 1.4666667
M27: =INDEX($B$4:$K$4,1)&", "&INDEX($B$4:$K$4,5)&", "&INDEX($B$4:$K$4,10) -> 11, 35, 85 | N27: =(INDEX($B$5:$K$5,1)+INDEX($B$5:$K$5,5)+INDEX($B$5:$K$5,10))/3 -> 1.4533333
M28: =INDEX($B$4:$K$4,1)&", "&INDEX($B$4:$K$4,6)&", "&INDEX($B$4:$K$4,7) -> 11, 55, 64 | N28: =(INDEX($B$5:$K$5,1)+INDEX($B$5:$K$5,6)+INDEX($B$5:$K$5,7))/3 -> 2.27
M29: =INDEX($B$4:$K$4,1)&", "&INDEX($B$4:$K$4,6)&", "&INDEX($B$4:$K$4,8) -> 11, 55, 65 | N29: =(INDEX($B$5:$K$5,1)+INDEX($B$5:$K$5,6)+INDEX($B$5:$K$5,8))/3 -> 2.1166667
M30: =INDEX($B$4:$K$4,1)&", "&INDEX($B$4:$K$4,6)&", "&INDEX($B$4:$K$4,9) -> 11, 55, 72 | N30: =(INDEX($B$5:$K$5,1)+INDEX($B$5:$K$5,6)+INDEX($B$5:$K$5,9))/3 -> 2.11
M31: =INDEX($B$4:$K$4,1)&", "&INDEX($B$4:$K$4,6)&", "&INDEX($B$4:$K$4,10) -> 11, 55, 85 | N31: =(INDEX($B$5:$K$5,1)+INDEX($B$5:$K$5,6)+INDEX($B$5:$K$5,10))/3 -> 2.0966667
M32: =INDEX($B$4:$K$4,1)&", "&INDEX($B$4:$K$4,7)&", "&INDEX($B$4:$K$4,8) -> 11, 64, 65 | N32: =(INDEX($B$5:$K$5,1)+INDEX($B$5:$K$5,7)+INDEX($B$5:$K$5,8))/3 -> 1.9633333
M33: =INDEX($B$4:$K$4,1)&", "&INDEX($B$4:$K$4,7)&", "&INDEX($B$4:$K$4,9) -> 11, 64, 72 | N33: =(INDEX($B$5:$K$5,1)+INDEX($B$5:$K$5,7)+INDEX($B$5:$K$5,9))/3 -> 1.9566667
M34: =INDEX($B$4:$K$4,1)&", "&INDEX($B$4:$K$4,7)&", "&INDEX($B$4:$K$4,10) -> 11, 64, 85 | N34: =(INDEX($B$5:$K$5,1)+INDEX($B$5:$K$5,7)+INDEX($B$5:$K$5,10))/3 -> 1.9433333
M35: =INDEX($B$4:$K$4,1)&", "&INDEX($B$4:$K$4,8)&", "&INDEX($B$4:$K$4,9) -> 11, 65, 72 | N35: =(INDEX($B$5:$K$5,1)+INDEX($B$5:$K$5,8)+INDEX($B$5:$K$5,9))/3 -> 1.8033333
M36: =INDEX($B$4:$K$4,1)&", "&INDEX($B$4:$K$4,8)&", "&INDEX($B$4:$K$4,10) -> 11, 65, 85 | N36: =(INDEX($B$5:$K$5,1)+INDEX($B$5:$K$5,8)+INDEX($B$5:$K$5,10))/3 -> 1.79
M37: =INDEX($B$4:$K$4,1)&", "&INDEX($B$4:$K$4,9)&", "&INDEX($B$4:$K$4,10) -> 11, 72, 85 | N37: =(INDEX($B$5:$K$5,1)+INDEX($B$5:$K$5,9)+INDEX($B$5:$K$5,10))/3 -> 1.7833333
M38: =INDEX($B$4:$K$4,2)&", "&INDEX($B$4:$K$4,3)&", "&INDEX($B$4:$K$4,4) -> 21, 23, 25 | N38: =(INDEX($B$5:$K$5,2)+INDEX($B$5:$K$5,3)+INDEX($B$5:$K$5,4))/3 -> 3.15
M39: =INDEX($B$4:$K$4,2)&", "&INDEX($B$4:$K$4,3)&", "&INDEX($B$4:$K$4,5) -> 21, 23, 35 | N39: =(INDEX($B$5:$K$5,2)+INDEX($B$5:$K$5,3)+INDEX($B$5:$K$5,5))/3 -> 2.8333333
M40: =INDEX($B$4:$K$4,2)&", "&INDEX($B$4:$K$4,3)&", "&INDEX($B$4:$K$4,6) -> 21, 23, 55 | N40: =(INDEX($B$5:$K$5,2)+INDEX($B$5:$K$5,3)+INDEX($B$5:$K$5,6))/3 -> 3.4766667
...
